Workbook
Name REGIME: Setup!$B$19
Name GATES: Setup!$E$13:$F$17
Name PROV_CREDIT: Setup!$E$20:$F$24
Name REGULATED: Setup!$B$19

Sheet Read Me
B2: Kin Score Worksheet
B3: Rubric 0.9.1 (2026-08-04) — the API Evangelist rating system, licensed by APIs.io
B5: What this is
B6: A working copy of the Kin Score rubric you can fill in for your own API program. It holds every one of the 106 checks in the composite score and all 14 Agent Readiness dimensions, with their real point values, and it reproduces the scorer's arithmetic in formulas — including the conditional regulatory facet, the N/A rules for contracts you don't publish, and the provenance multiplier. Tick a check off and every number moves.
B8: How to use it
B9: 1. Setup tab — name your program and answer the four 'what do you publish' questions. Pick your regulatory regime, or leave it as none.
B10: 2. Checklist tab — work down it and set Status to Yes / Partial / No. Yellow cells are yours; everything else calculates. Use the Coverage column when a check is true of some of your contracts but not all — the scorer averages spec checks across every document you publish, so 6 of 10 specs with good summaries is 60%, not a pass.
B11: 3. Priorities tab — reads back the highest-value unfinished work, ranked by what each check is actually worth to your score today.
B12: 4. Scorecard tab — your composite, your band, and where the remaining points sit.
B13: 5. Agent Readiness tab — scored separately and never blended into the composite. Several dimensions are graded rather than pass/fail; the grades available are listed on each row.
B15: The arithmetic
B16: Each check awards points to one facet. A facet's sub-score is points earned ÷ points available for that facet, as a 0–100. The composite is the weighted sum of the facet sub-scores.
... B34: Every input to this score is a public, machine-checkable signal you chose to publish or chose to leave out. No human quietly adds or removes points.

Sheet Setup
A1: Kin Score Worksheet — Setup
A2: Fill in the yellow cells. They switch whole blocks of checks on or off, exactly the way the scorer does.
A4: Your API program
A5: Provider name
A6: APIs.io provider slug
A7: Assessment date
A8: Assessed by
A10: What you publish today
A11: A contract you do not publish is not counted against you — those checks leave the denominator entirely. Answer honestly; overstating here inflates the whole sheet.
A12: Do you publish an OpenAPI (or Swagger 2.0) contract? | B12: Yes | C12: Switches on the 17 spec-level OpenAPI checks. | E12: gate | F12: applies | H12: regime ids
A13: Do you publish an AsyncAPI document? | B13: No | C13: Switches on the 5 spec-level AsyncAPI checks. | E13: always | F13: Yes | H13: none
A14: Do you publish a GraphQL SDL? | B14: No | C14: Switches on the 3 GraphQL checks. Not a GraphQL shop = not penalised. | E14: openapi | F14: =B12 | H14: banking_open_finance
A15: Do you publish a FHIR CapabilityStatement? | B15: No | C15: Switches on the 2 FHIR checks. Not a FHIR server = not penalised. | E15: asyncapi | F15: =B13 | H15: securities_market_data
E16: graphql | F16: =B14 | H16: health
A17: Regulated industry | E17: fhir | F17: =B15 | H17: payments
A18: The regulatory facet is conditional. Pick the regime your tags match — see the 'Regulated Industries' tab — or leave it as none. Most-specific regime wins. | H18: insurance
A19: Regime | B19: none | C19: When set, the regulatory facet takes 15% of the composite and the other six scale to the remaining 85%. | E19: authorship | F19: credit | H19: telecommunications
E20: — | F20: 1 | H20: energy_utilities
E21: first-party | F21: 1 | H21: government
E22: conformance | F22: 0.75
E23: derived | F23: 0.25
E24: unknown | F24: 1

Sheet Scorecard
A1: Kin Score — Scorecard
A2: =IF(Setup!B5="","(name your provider on the Setup tab)",Setup!B5)
A3: Rubric 0.9.1 (2026-08-04). Every number here is computed from the Checklist tab — nothing on this sheet is typed.
A5: Facet | B5: Weight | C5: Effective weight | D5: Points available | E5: Points earned | F5: Sub-score (0–100) | G5: Contribution | I5: What it measures
A6: Discoverability | B6: 0.1 | C6: =IF(REGIME="none",$B6,$B6*0.85) | D6: =SUMIF(Checklist!$B$2:$B$107,$A6,Checklist!$L$2:$L$107) | E6: =SUMIF(Checklist!$B$2:$B$107,$A6,Checklist!$K$2:$K$107) | F6: =IF($D6=0,0,ROUND($E6/$D6*100,1)) | G6: =ROUND($C6*$F6,2) | I6: Can the API be found and understood from machine-readable metadata alone? Driven by apis.yml completeness, tagging, and identity signals.
A7: Contract Quality | B7: 0.25 | C7: =IF(REGIME="none",$B7,$B7*0.85) | D7: =SUMIF(Checklist!$B$2:$B$107,$A7,Checklist!$L$2:$L$107) | E7: =SUMIF(Checklist!$B$2:$B$107,$A7,Checklist!$K$2:$K$107) | F7: =IF($D7=0,0,ROUND($E7/$D7*100,1)) | G7: =ROUND($C7*$F7,2) | I7: Technical depth and richness of the API contract artifacts — OpenAPI, AsyncAPI, JSON Schema, JSON-LD.
A8: Governance | B8: 0.12 | C8: =IF(REGIME="none",$B8,$B8*0.85) | D8: =SUMIF(Checklist!$B$2:$B$107,$A8,Checklist!$L$2:$L$107) | E8: =SUMIF(Checklist!$B$2:$B$107,$A8,Checklist!$K$2:$K$107) | F8: =IF($D8=0,0,ROUND($E8/$D8*100,1)) | G8: =ROUND($C8*$F8,2) | I8: Outcomes of Spectral linting and presence of governance artifacts (rulesets, vocabulary). Severity-weighted.
A9: Operational Transparency | B9: 0.13 | C9: =IF(REGIME="none",$B9,$B9*0.85) | D9: =SUMIF(Checklist!$B$2:$B$107,$A9,Checklist!$L$2:$L$107) | E9: =SUMIF(Checklist!$B$2:$B$107,$A9,Checklist!$K$2:$K$107) | F9: =IF($D9=0,0,ROUND($E9/$D9*100,1)) | G9: =ROUND($C9*$F9,2) | I9: Does the provider expose how the API behaves operationally? Rate limits, status, change log, deprecation, security disclosure.
A10: Developer Ergonomics | B10: 0.2 | C10: =IF(REGIME="none",$B10,$B10*0.85) | D10: =SUMIF(Checklist!$B$2:$B$107,$A10,Checklist!$L$2:$L$107) | E10: =SUMIF(Checklist!$B$2:$B$107,$A10,Checklist!$K$2:$K$107) | F10: =IF($D10=0,0,ROUND($E10/$D10*100,1)) | G10: =ROUND($C10*$F10,2) | I10: How easy is it to get started? SDKs, CLI, portal, getting-started, documentation, sandbox/console, MCP server, and authentication clarity.
A11: Commercial Clarity | B11: 0.2 | C11: =IF(REGIME="none",$B11,$B11*0.85) | D11: =SUMIF(Checklist!$B$2:$B$107,$A11,Checklist!$L$2:$L$107) | E11: =SUMIF(Checklist!$B$2:$B$107,$A11,Checklist!$K$2:$K$107) | F11: =IF($D11=0,0,ROUND($E11/$D11*100,1)) | G11: =ROUND($C11*$F11,2) | I11: Are commercial terms machine-readable? Plans, pricing, sign-up, terms of service, privacy, finops mapping, compliance/trust.
A12: Regulatory Posture | B12: 0.15 | C12: =IF(REGIME="none",0,0.15) | D12: =SUMIF(Checklist!$B$2:$B$107,$A12,Checklist!$L$2:$L$107) | E12: =SUMIF(Checklist!$B$2:$B$107,$A12,Checklist!$K$2:$K$107) | F12: =IF($D12=0,0,ROUND($E12/$D12*100,1)) | G12: =ROUND($C12*$F12,2) | I12: For providers in a regulated industry ONLY: does the API publish the consent, security, legal, and standards-conformance posture its regime demands? Consent-scoped authorization (OAuth/OIDC scopes), a published security + vulnerability-disclosure posture, terms/privacy as legal basis, and evidence of conformance to the industry's data standard. Not applied to unregulated industries — see the composite math note below.
A13: COMPOSITE — your Kin Score | F13: =ROUND(SUM($G$6:$G$12),1)
A14: Band | F14: =IF($F$13>=66,"Exemplar",IF($F$13>=56,"Strong",IF($F$13>=42,"Developing",IF($F$13>=28,"Thin",IF($F$13>=13,"Emerging","Minimal"))))) | I14: =VLOOKUP($F$14,Bands!$A$4:$D$9,4,FALSE)
A16: Where the next points are
A17: Checks passing | F17: =COUNTIFS(Checklist!$F$2:$F$107,"Yes",Checklist!$G$2:$G$107,"Yes")
A18: Checks that apply to you | F18: =COUNTIF(Checklist!$F$2:$F$107,"Yes")
A19: Checks not applicable | F19: =COUNTIF(Checklist!$F$2:$F$107,"N/A")
A20: Composite points still on the table | F20: =ROUND(SUM(Checklist!$N$2:$N$107),1)
A21: Biggest single win | F21: =Priorities!$D$4 | I21: =IF(Priorities!$B$4="","nothing left that applies to you",Priorities!$B$4&" ("&Priorities!$C$4&")")
A23: Agent Readiness (scored separately, never blended in)
A24: Score | F24: ='Agent Readiness'!$C$2
A25: Band | F25: ='Agent Readiness'!$C$3 | I25: A composite in the Strong band and a human-only Agent Readiness is a normal, and increasingly expensive, combination.

Sheet Checklist
A1: Artifact | B1: Facet | C1: Check ID | D1: Check | E1: Points | F1: Applies | G1: Status | H1: Coverage | I1: Authorship | J1: Credit | K1: Earned | L1: Counts for | M1: Gap | N1: Worth on your score | O1: What the scorer looks for | P1: Why it matters | Q1: Owner | R1: Target | S1: Notes | T1: _gate | U1: _regimes | V1: _rank
A2: apis.yml | B2: Discoverability | C2: apis_yml_present | D2: Publishes an apis.yml index | E2: 10 | F2: =IF(AND($U2<>"",REGIME="none"),"N/A",IF(AND($U2<>"",$U2<>"any",ISERROR(SEARCH(REGIME,$U2))),"N/A",IF(VLOOKUP($T2,GATES,2,FALSE)="Yes","Yes","N/A"))) | G2: No | I2: — | J2: =IFERROR(VLOOKUP($I2,PROV_CREDIT,2,FALSE),1) | K2: =IF($F2="N/A",0,$E2*IF(ISNUMBER($H2),MEDIAN(0,$H2,1),IF($G2="Yes",1,IF($G2="Partial",0.5,0)))*$J2) | L2: =IF($F2="N/A",0,$E2) | M2: =$L2-$K2 | N2: =IF($L2=0,0,ROUND($M2/SUMIF($B$2:$B$107,$B2,$L$2:$L$107)*100*IFERROR(VLOOKUP($B2,Scorecard!$A$6:$C$12,3,FALSE),0),2)) | O2: source_filename == "apis.yml" | P2: The provider maintains a real APIs.json index rather than being catalogued from the outside. The single highest-value discoverability signal: it is the difference between a provider describing itself and being described. | T2: always | V2: =$N2-ROW()/100000
A3: apis.yml | B3: Discoverability | C3: description_substantive | D3: Substantive description | E3: 5 | F3: =IF(AND($U3<>"",REGIME="none"),"N/A",IF(AND($U3<>"",$U3<>"any",ISERROR(SEARCH(REGIME,$U3))),"N/A",IF(VLOOKUP($T3,GATES,2,FALSE)="Yes","Yes","N/A"))) | G3: No | I3: — | J3: =IFERROR(VLOOKUP($I3,PROV_CREDIT,2,FALSE),1) | K3: =IF($F3="N/A",0,$E3*IF(ISNUMBER($H3),MEDIAN(0,$H3,1),IF($G3="Yes",1,IF($G3="Partial",0.5,0)))*$J3) | L3: =IF($F3="N/A",0,$E3) | M3: =$L3-$K3 | N3: =IF($L3=0,0,ROUND($M3/SUMIF($B$2:$B$107,$B3,$L$2:$L$107)*100*IFERROR(VLOOKUP($B3,Scorecard!$A$6:$C$12,3,FALSE),0),2)) | O3: len(description) >= 200 | P3: At least 200 characters of description. Enough for a human or an agent to decide whether the API is relevant without opening the site. | T3: always | V3: =$N3-ROW()/100000
A4: apis.yml | B4: Discoverability | C4: tags_present | D4: Tagged for discovery | E4: 5 | F4: =IF(AND($U4<>"",REGIME="none"),"N/A",IF(AND($U4<>"",$U4<>"any",ISERROR(SEARCH(REGIME,$U4))),"N/A",IF(VLOOKUP($T4,GATES,2,FALSE)="Yes","Yes","N/A"))) | G4: No | I4: — | J4: =IFERROR(VLOOKUP($I4,PROV_CREDIT,2,FALSE),1) | K4: =IF($F4="N/A",0,$E4*IF(ISNUMBER($H4),MEDIAN(0,$H4,1),IF($G4="Yes",1,IF($G4="Partial",0.5,0)))*$J4) | L4: =IF($F4="N/A",0,$E4) | M4: =$L4-$K4 | N4: =IF($L4=0,0,ROUND($M4/SUMIF($B$2:$B$107,$B4,$L$2:$L$107)*100*IFERROR(VLOOKUP($B4,Scorecard!$A$6:$C$12,3,FALSE),0),2)) | O4: len(tags) >= 5 | P4: Five or more tags. Tags are how the API surfaces in topical search and how it gets placed into industries and areas rather than sitting unclassified. | T4: always | V4: =$N4-ROW()/100000
A5: apis.yml | B5: Discoverability | C5: image_present | D5: Provider image | E5: 2 | F5: =IF(AND($U5<>"",REGIME="none"),"N/A",IF(AND($U5<>"",$U5<>"any",ISERROR(SEARCH(REGIME,$U5))),"N/A",IF(VLOOKUP($T5,GATES,2,FALSE)="Yes","Yes","N/A"))) | G5: No | I5: — | J5: =IFERROR(VLOOKUP($I5,PROV_CREDIT,2,FALSE),1) | K5: =IF($F5="N/A",0,$E5*IF(ISNUMBER($H5),MEDIAN(0,$H5,1),IF($G5="Yes",1,IF($G5="Partial",0.5,0)))*$J5) | L5: =IF($F5="N/A",0,$E5) | M5: =$L5-$K5 | N5: =IF($L5=0,0,ROUND($M5/SUMIF($B$2:$B$107,$B5,$L$2:$L$107)*100*IFERROR(VLOOKUP($B5,Scorecard!$A$6:$C$12,3,FALSE),0),2)) | O5: image is set | P5: A logo or image is referenced, so the provider renders as a recognizable card in search results and listings instead of a bare line of text. | T5: always | V5: =$N5-ROW()/100000
A6: apis.yml | B6: Discoverability | C6: maintainer_present | D6: Named maintainer | E6: 3 | F6: =IF(AND($U6<>"",REGIME="none"),"N/A",IF(AND($U6<>"",$U6<>"any",ISERROR(SEARCH(REGIME,$U6))),"N/A",IF(VLOOKUP($T6,GATES,2,FALSE)="Yes","Yes","N/A"))) | G6: No | I6: — | J6: =IFERROR(VLOOKUP($I6,PROV_CREDIT,2,FALSE),1) | K6: =IF($F6="N/A",0,$E6*IF(ISNUMBER($H6),MEDIAN(0,$H6,1),IF($G6="Yes",1,IF($G6="Partial",0.5,0)))*$J6) | L6: =IF($F6="N/A",0,$E6) | M6: =$L6-$K6 | N6: =IF($L6=0,0,ROUND($M6/SUMIF($B$2:$B$107,$B6,$L$2:$L$107)*100*IFERROR(VLOOKUP($B6,Scorecard!$A$6:$C$12,3,FALSE),0),2)) | O6: maintainers[0].email is set | P6: A contactable maintainer email. Establishes that someone owns the index and gives consumers a route to reach them. | T6: always | V6: =$N6-ROW()/100000
A7: apis.yml | B7: Discoverability | C7: created_modified_dates | D7: Created and modified dates | E7: 2 | F7: =IF(AND($U7<>"",REGIME="none"),"N/A",IF(AND($U7<>"",$U7<>"any",ISERROR(SEARCH(REGIME,$U7))),"N/A",IF(VLOOKUP($T7,GATES,2,FALSE)="Yes","Yes","N/A"))) | G7: No | I7: — | J7: =IFERROR(VLOOKUP($I7,PROV_CREDIT,2,FALSE),1) | K7: =IF($F7="N/A",0,$E7*IF(ISNUMBER($H7),MEDIAN(0,$H7,1),IF($G7="Yes",1,IF($G7="Partial",0.5,0)))*$J7) | L7: =IF($F7="N/A",0,$E7) | M7: =$L7-$K7 | N7: =IF($L7=0,0,ROUND($M7/SUMIF($B$2:$B$107,$B7,$L$2:$L$107)*100*IFERROR(VLOOKUP($B7,Scorecard!$A$6:$C$12,3,FALSE),0),2)) | O7: created and modified both ISO dates | P7: Both timestamps present as ISO dates, so freshness is machine-readable and a consumer can tell a maintained index from an abandoned one. | T7: always | V7: =$N7-ROW()/100000
A8: apis.yml | B8: Discoverability | C8: multiple_apis | D8: Indexes three or more APIs | E8: 3 | F8: =IF(AND($U8<>"",REGIME="none"),"N/A",IF(AND($U8<>"",$U8<>"any",ISERROR(SEARCH(REGIME,$U8))),"N/A",IF(VLOOKUP($T8,GATES,2,FALSE)="Yes","Yes","N/A"))) | G8: No | I8: — | J8: =IFERROR(VLOOKUP($I8,PROV_CREDIT,2,FALSE),1) | K8: =IF($F8="N/A",0,$E8*IF(ISNUMBER($H8),MEDIAN(0,$H8,1),IF($G8="Yes",1,IF($G8="Partial",0.5,0)))*$J8) | L8: =IF($F8="N/A",0,$E8) | M8: =$L8-$K8 | N8: =IF($L8=0,0,ROUND($M8/SUMIF($B$2:$B$107,$B8,$L$2:$L$107)*100*IFERROR(VLOOKUP($B8,Scorecard!$A$6:$C$12,3,FALSE),0),2)) | O8: api_count >= 3 | P8: The index covers a real surface rather than a single endpoint — evidence the provider is cataloguing their whole platform. | T8: always | V8: =$N8-ROW()/100000
A9: apis.yml | B9: Discoverability | C9: human_url_per_api | D9: Human URL on every API | E9: 5 | F9: =IF(AND($U9<>"",REGIME="none"),"N/A",IF(AND($U9<>"",$U9<>"any",ISERROR(SEARCH(REGIME,$U9))),"N/A",IF(VLOOKUP($T9,GATES,2,FALSE)="Yes","Yes","N/A"))) | G9: No | I9: — | J9: =IFERROR(VLOOKUP($I9,PROV_CREDIT,2,FALSE),1) | K9: =IF($F9="N/A",0,$E9*IF(ISNUMBER($H9),MEDIAN(0,$H9,1),IF($G9="Yes",1,IF($G9="Partial",0.5,0)))*$J9) | L9: =IF($F9="N/A",0,$E9) | M9: =$L9-$K9 | N9: =IF($L9=0,0,ROUND($M9/SUMIF($B$2:$B$107,$B9,$L$2:$L$107)*100*IFERROR(VLOOKUP($B9,Scorecard!$A$6:$C$12,3,FALSE),0),2)) | O9: every api has humanURL | P9: Each indexed API points at documentation a person can read. Without it, an entry is a name with nowhere to go. | T9: always | V9: =$N9-ROW()/100000
A10: apis.yml | B10: Discoverability | C10: base_url_per_api | D10: Base URL on every API | E10: 5 | F10: =IF(AND($U10<>"",REGIME="none"),"N/A",IF(AND($U10<>"",$U10<>"any",ISERROR(SEARCH(REGIME,$U10))),"N/A",IF(VLOOKUP($T10,GATES,2,FALSE)="Yes","Yes","N/A"))) | G10: No | I10: — | J10: =IFERROR(VLOOKUP($I10,PROV_CREDIT,2,FALSE),1) | K10: =IF($F10="N/A",0,$E10*IF(ISNUMBER($H10),MEDIAN(0,$H10,1),IF($G10="Yes",1,IF($G10="Partial",0.5,0)))*$J10) | L10: =IF($F10="N/A",0,$E10) | M10: =$L10-$K10 | N10: =IF($L10=0,0,ROUND($M10/SUMIF($B$2:$B$107,$B10,$L$2:$L$107)*100*IFERROR(VLOOKUP($B10,Scorecard!$A$6:$C$12,3,FALSE),0),2)) | O10: every api has baseURL and no baseURL contains "localhost" | P10: Each indexed API declares a real, callable base URL. A localhost base URL fails this check — it signals a spec that was published without ever being pointed at production. | T10: always | V10: =$N10-ROW()/100000
A11: apis.yml | B11: Discoverability | C11: well_known_published | D11: Serves a .well-known surface | E11: 6 | F11: =IF(AND($U11<>"",REGIME="none"),"N/A",IF(AND($U11<>"",$U11<>"any",ISERROR(SEARCH(REGIME,$U11))),"N/A",IF(VLOOKUP($T11,GATES,2,FALSE)="Yes","Yes","N/A"))) | G11: No | I11: — | J11: =IFERROR(VLOOKUP($I11,PROV_CREDIT,2,FALSE),1) | K11: =IF($F11="N/A",0,$E11*IF(ISNUMBER($H11),MEDIAN(0,$H11,1),IF($G11="Yes",1,IF($G11="Partial",0.5,0)))*$J11) | L11: =IF($F11="N/A",0,$E11) | M11: =$L11-$K11 | N11: =IF($L11=0,0,ROUND($M11/SUMIF($B$2:$B$107,$B11,$L$2:$L$107)*100*IFERROR(VLOOKUP($B11,Scorecard!$A$6:$C$12,3,FALSE),0),2)) | O11: well-known/ carries an api-catalog, security.txt, or a protected-resource doc | P11: The provider serves machine entrypoints at RFC 8615 well-known paths — an api-catalog linkset (RFC 9727), a security.txt, an OAuth protected-resource document. This is the address an agent tries FIRST, before it has read anything, and it is the discoverability signal a marketing site cannot fake. | T11: always | V11: =$N11-ROW()/100000
A12: apis.yml | B12: Discoverability | C12: llms_txt_published | D12: Publishes llms.txt | E12: 4 | F12: =IF(AND($U12<>"",REGIME="none"),"N/A",IF(AND($U12<>"",$U12<>"any",ISERROR(SEARCH(REGIME,$U12))),"N/A",IF(VLOOKUP($T12,GATES,2,FALSE)="Yes","Yes","N/A"))) | G12: No | I12: — | J12: =IFERROR(VLOOKUP($I12,PROV_CREDIT,2,FALSE),1) | K12: =IF($F12="N/A",0,$E12*IF(ISNUMBER($H12),MEDIAN(0,$H12,1),IF($G12="Yes",1,IF($G12="Partial",0.5,0)))*$J12) | L12: =IF($F12="N/A",0,$E12) | M12: =$L12-$K12 | N12: =IF($L12=0,0,ROUND($M12/SUMIF($B$2:$B$107,$B12,$L$2:$L$107)*100*IFERROR(VLOOKUP($B12,Scorecard!$A$6:$C$12,3,FALSE),0),2)) | O12: llms/ carries an llms.txt | P12: An llms.txt — the provider stating, in a machine-readable file at a conventional path, what a language model should read to understand the product. Young, unratified, and adopted by 6,012 providers in this catalog, which makes it the fastest-moving machine-discoverability signal there is. | T12: always | V12: =$N12-ROW()/100000
A13: apis.yml | B13: Discoverability | C13: apis_json_self_hosted | D13: Self-hosts the APIs.json index | E13: 4 | F13: =IF(AND($U13<>"",REGIME="none"),"N/A",IF(AND($U13<>"",$U13<>"any",ISERROR(SEARCH(REGIME,$U13))),"N/A",IF(VLOOKUP($T13,GATES,2,FALSE)="Yes","Yes","N/A"))) | G13: No | I13: — | J13: =IFERROR(VLOOKUP($I13,PROV_CREDIT,2,FALSE),1) | K13: =IF($F13="N/A",0,$E13*IF(ISNUMBER($H13),MEDIAN(0,$H13,1),IF($G13="Yes",1,IF($G13="Partial",0.5,0)))*$J13) | L13: =IF($F13="N/A",0,$E13) | M13: =$L13-$K13 | N13: =IF($L13=0,0,ROUND($M13/SUMIF($B$2:$B$107,$B13,$L$2:$L$107)*100*IFERROR(VLOOKUP($B13,Scorecard!$A$6:$C$12,3,FALSE),0),2)) | O13: apis.yml url points at a host the provider controls, not the catalog | P13: The provider serves its own APIs.json index from its own domain rather than being catalogued from the outside. `apis_yml_present` above rewards the index existing; this rewards the provider OWNING it — the difference between describing yourself and being described. | T13: always | V13: =$N13-ROW()/100000
... A97: Regulatory Posture | B97: Regulatory Posture | C97: reg_standards_conformance | D97: Data-standard conformance | E97: 5 | F97: =IF(AND($U97<>"",REGIME="none"),"N/A",IF(AND($U97<>"",$U97<>"any",ISERROR(SEARCH(REGIME,$U97))),"N/A",IF(VLOOKUP($T97,GATES,2,FALSE)="Yes","Yes","N/A"))) | G97: No | I97: — | J97: =IFERROR(VLOOKUP($I97,PROV_CREDIT,2,FALSE),1) | K97: =IF($F97="N/A",0,$E97*IF(ISNUMBER($H97),MEDIAN(0,$H97,1),IF($G97="Yes",1,IF($G97="Partial",0.5,0)))*$J97) | L97: =IF($F97="N/A",0,$E97) | M97: =$L97-$K97 | N97: =IF($L97=0,0,ROUND($M97/SUMIF($B$2:$B$107,$B97,$L$2:$L$107)*100*IFERROR(VLOOKUP($B97,Scorecard!$A$6:$C$12,3,FALSE),0),2)) | O97: implements a recognized data standard — common[].type includes "Standard"/"Conformance", or a Vocabulary/JSON-LD context is published | P97: Evidence the API conforms to the industry's data standard (a named standard, conformance artifact, or a published vocabulary/JSON-LD context). In a regulated space, speaking the mandated shape is the difference between interoperable and merely present. | T97: always | V97: =$N97-ROW()/100000
A98: Regulatory Posture | B98: Regulatory Posture | C98: reg_named_standard_conformance | D98: Conforms to the standard named for its regime | E98: 8 | F98: =IF(AND($U98<>"",REGIME="none"),"N/A",IF(AND($U98<>"",$U98<>"any",ISERROR(SEARCH(REGIME,$U98))),"N/A",IF(VLOOKUP($T98,GATES,2,FALSE)="Yes","Yes","N/A"))) | G98: No | I98: — | J98: =IFERROR(VLOOKUP($I98,PROV_CREDIT,2,FALSE),1) | K98: =IF($F98="N/A",0,$E98*IF(ISNUMBER($H98),MEDIAN(0,$H98,1),IF($G98="Yes",1,IF($G98="Partial",0.5,0)))*$J98) | L98: =IF($F98="N/A",0,$E98) | M98: =$L98-$K98 | N98: =IF($L98=0,0,ROUND($M98/SUMIF($B$2:$B$107,$B98,$L$2:$L$107)*100*IFERROR(VLOOKUP($B98,Scorecard!$A$6:$C$12,3,FALSE),0),2)) | O98: conformance/ declares conformance to a standard listed under the matched regime`s `standards:` — not merely a generic Standard tag | P98: The provider conforms to the standard RECOGNIZED FOR ITS REGIME, resolved against the standards catalog: OBIE, the DSB Consumer Data Standards, FDX or Berlin Group for open banking; US Core / USCDI for health; ACORD, CIECA or CSIO for insurance; CAMARA or TM Forum for telecom; Green Button / ESPI or cds-energy for energy. This supersedes the generic check above in strength for a reason the banking quartet made plain: a `Standard` tag credits an intention, while naming the instrument credits a fact. It is also the check the insurance quartet needed to state its emptiest finding honestly — ACORD is live inside a machine-readable contract at exactly one company worldwide. | T98: always | U98: any | V98: =$N98-ROW()/100000
A99: Regulatory Posture | B99: Regulatory Posture | C99: reg_fapi_profile | D99: FAPI / hardened authorization profile | E99: 6 | F99: =IF(AND($U99<>"",REGIME="none"),"N/A",IF(AND($U99<>"",$U99<>"any",ISERROR(SEARCH(REGIME,$U99))),"N/A",IF(VLOOKUP($T99,GATES,2,FALSE)="Yes","Yes","N/A"))) | G99: No | I99: — | J99: =IFERROR(VLOOKUP($I99,PROV_CREDIT,2,FALSE),1) | K99: =IF($F99="N/A",0,$E99*IF(ISNUMBER($H99),MEDIAN(0,$H99,1),IF($G99="Yes",1,IF($G99="Partial",0.5,0)))*$J99) | L99: =IF($F99="N/A",0,$E99) | M99: =$L99-$K99 | N99: =IF($L99=0,0,ROUND($M99/SUMIF($B$2:$B$107,$B99,$L$2:$L$107)*100*IFERROR(VLOOKUP($B99,Scorecard!$A$6:$C$12,3,FALSE),0),2)) | O99: conformance declares FAPI or FAPI 2.0, or auth artifacts document PAR, private_key_jwt or mTLS-bound tokens | P99: The security profile CDR, UK Open Banking and PSD2 actually mandate, beyond generic OAuth: the FAPI profile, pushed authorization requests, private_key_jwt client authentication, mTLS-bound tokens. Generic OAuth is table stakes; this is the stack the regime specifies. | T99: always | U99: banking_open_finance | V99: =$N99-ROW()/100000
A100: Regulatory Posture | B100: Regulatory Posture | C100: reg_consent_model | D100: Published consent model | E100: 7 | F100: =IF(AND($U100<>"",REGIME="none"),"N/A",IF(AND($U100<>"",$U100<>"any",ISERROR(SEARCH(REGIME,$U100))),"N/A",IF(VLOOKUP($T100,GATES,2,FALSE)="Yes","Yes","N/A"))) | G100: No | I100: — | J100: =IFERROR(VLOOKUP($I100,PROV_CREDIT,2,FALSE),1) | K100: =IF($F100="N/A",0,$E100*IF(ISNUMBER($H100),MEDIAN(0,$H100,1),IF($G100="Yes",1,IF($G100="Partial",0.5,0)))*$J100) | L100: =IF($F100="N/A",0,$E100) | M100: =$L100-$K100 | N100: =IF($L100=0,0,ROUND($M100/SUMIF($B$2:$B$107,$B100,$L$2:$L$107)*100*IFERROR(VLOOKUP($B100,Scorecard!$A$6:$C$12,3,FALSE),0),2)) | O100: a machine-readable consent surface — consent scopes, a FHIR Consent resource, a CDR consent artifact, or a documented consent/authorization model | P100: A consent surface a machine can read. This is the structural gap the whole series found and the reason it is weighted where it is: in market after market whose entire premise is consumer consent, machine-readable consent ran in the single digits. A FHIR Consent resource is exposed by essentially nobody; insurance ran at 2.5% in the US and zero among every market's leaders, in the most personally-invasive data business in the economy. Weighted heaviest in insurance and telecom precisely BECAUSE no rule compels it there — where consent is unmandated its presence is a genuine differentiator rather than a compliance artifact. | T100: always | U100: banking_open_finance,health,insurance,telecommunications,energy_utilities | V100: =$N100-ROW()/100000
A101: Regulatory Posture | B101: Regulatory Posture | C101: reg_write_surface | D101: Action / write surface | E101: 4 | F101: =IF(AND($U101<>"",REGIME="none"),"N/A",IF(AND($U101<>"",$U101<>"any",ISERROR(SEARCH(REGIME,$U101))),"N/A",IF(VLOOKUP($T101,GATES,2,FALSE)="Yes","Yes","N/A"))) | G101: No | I101: — | J101: =IFERROR(VLOOKUP($I101,PROV_CREDIT,2,FALSE),1) | K101: =IF($F101="N/A",0,$E101*IF(ISNUMBER($H101),MEDIAN(0,$H101,1),IF($G101="Yes",1,IF($G101="Partial",0.5,0)))*$J101) | L101: =IF($F101="N/A",0,$E101) | M101: =$L101-$K101 | N101: =IF($L101=0,0,ROUND($M101/SUMIF($B$2:$B$107,$B101,$L$2:$L$107)*100*IFERROR(VLOOKUP($B101,Scorecard!$A$6:$C$12,3,FALSE),0),2)) | O101: the contract exposes payment initiation, VRP, or another mutating regulated operation | P101: The regime is actionable, not read-only. An agent that can move money on an account is a different animal from one that can only read it, and the score should say so: the UK — which mandated payment initiation — scored 87% on idempotency, where read-only Australia scored 0%. | T101: always | U101: banking_open_finance,payments | V101: =$N101-ROW()/100000
A102: Regulatory Posture | B102: Regulatory Posture | C102: reg_smart_configuration | D102: SMART-on-FHIR configuration served | E102: 6 | F102: =IF(AND($U102<>"",REGIME="none"),"N/A",IF(AND($U102<>"",$U102<>"any",ISERROR(SEARCH(REGIME,$U102))),"N/A",IF(VLOOKUP($T102,GATES,2,FALSE)="Yes","Yes","N/A"))) | G102: No | I102: — | J102: =IFERROR(VLOOKUP($I102,PROV_CREDIT,2,FALSE),1) | K102: =IF($F102="N/A",0,$E102*IF(ISNUMBER($H102),MEDIAN(0,$H102,1),IF($G102="Yes",1,IF($G102="Partial",0.5,0)))*$J102) | L102: =IF($F102="N/A",0,$E102) | M102: =$L102-$K102 | N102: =IF($L102=0,0,ROUND($M102/SUMIF($B$2:$B$107,$B102,$L$2:$L$107)*100*IFERROR(VLOOKUP($B102,Scorecard!$A$6:$C$12,3,FALSE),0),2)) | O102: a .well-known/smart-configuration is served, or SMART scopes are published | P102: A served `.well-known/smart-configuration` with published SMART-on-FHIR scopes. The structural finding across all four healthcare markets: the security scopes often exist, but the smart-configuration is served almost nowhere — so the check has to weight a DISCOVERABLE, consent-legible surface rather than the mere presence of scopes somewhere in prose. | T102: always | U102: health | V102: =$N102-ROW()/100000
A103: Regulatory Posture | B103: Regulatory Posture | C103: reg_pci_sca | D103: PCI scope and strong customer authentication | E103: 6 | F103: =IF(AND($U103<>"",REGIME="none"),"N/A",IF(AND($U103<>"",$U103<>"any",ISERROR(SEARCH(REGIME,$U103))),"N/A",IF(VLOOKUP($T103,GATES,2,FALSE)="Yes","Yes","N/A"))) | G103: No | I103: — | J103: =IFERROR(VLOOKUP($I103,PROV_CREDIT,2,FALSE),1) | K103: =IF($F103="N/A",0,$E103*IF(ISNUMBER($H103),MEDIAN(0,$H103,1),IF($G103="Yes",1,IF($G103="Partial",0.5,0)))*$J103) | L103: =IF($F103="N/A",0,$E103) | M103: =$L103-$K103 | N103: =IF($L103=0,0,ROUND($M103/SUMIF($B$2:$B$107,$B103,$L$2:$L$107)*100*IFERROR(VLOOKUP($B103,Scorecard!$A$6:$C$12,3,FALSE),0),2)) | O103: PCI-DSS attestation or scope disclosure, plus 3-D Secure / SCA support | P103: PCI-DSS attestation or scope disclosure together with strong customer authentication (3-D Secure, PSD2 SCA). The two disclosures every payments regime is built on, and the ones a merchant's own auditor will ask for first. | T103: always | U103: payments | V103: =$N103-ROW()/100000
A104: Regulatory Posture | B104: Regulatory Posture | C104: reg_entitlement_terms | D104: Machine-readable entitlement and redistribution terms | E104: 6 | F104: =IF(AND($U104<>"",REGIME="none"),"N/A",IF(AND($U104<>"",$U104<>"any",ISERROR(SEARCH(REGIME,$U104))),"N/A",IF(VLOOKUP($T104,GATES,2,FALSE)="Yes","Yes","N/A"))) | G104: No | I104: — | J104: =IFERROR(VLOOKUP($I104,PROV_CREDIT,2,FALSE),1) | K104: =IF($F104="N/A",0,$E104*IF(ISNUMBER($H104),MEDIAN(0,$H104,1),IF($G104="Yes",1,IF($G104="Partial",0.5,0)))*$J104) | L104: =IF($F104="N/A",0,$E104) | M104: =$L104-$K104 | N104: =IF($L104=0,0,ROUND($M104/SUMIF($B$2:$B$107,$B104,$L$2:$L$107)*100*IFERROR(VLOOKUP($B104,Scorecard!$A$6:$C$12,3,FALSE),0),2)) | O104: redistribution / entitlement / data-licensing terms published as machine-readable data | P104: Entitlement and redistribution terms in machine-readable form, plus MiFID II or exchange data-licensing disclosure. In market data the licence IS the product boundary, and a consumer who cannot read it programmatically cannot build against it safely. | T104: always | U104: securities_market_data | V104: =$N104-ROW()/100000
A105: Regulatory Posture | B105: Regulatory Posture | C105: reg_certification_signal | D105: Third-party certification | E105: 5 | F105: =IF(AND($U105<>"",REGIME="none"),"N/A",IF(AND($U105<>"",$U105<>"any",ISERROR(SEARCH(REGIME,$U105))),"N/A",IF(VLOOKUP($T105,GATES,2,FALSE)="Yes","Yes","N/A"))) | G105: No | I105: — | J105: =IFERROR(VLOOKUP($I105,PROV_CREDIT,2,FALSE),1) | K105: =IF($F105="N/A",0,$E105*IF(ISNUMBER($H105),MEDIAN(0,$H105,1),IF($G105="Yes",1,IF($G105="Partial",0.5,0)))*$J105) | L105: =IF($F105="N/A",0,$E105) | M105: =$L105-$K105 | N105: =IF($L105=0,0,ROUND($M105/SUMIF($B$2:$B$107,$B105,$L$2:$L$107)*100*IFERROR(VLOOKUP($B105,Scorecard!$A$6:$C$12,3,FALSE),0),2)) | O105: a public, independently-issued certification is held and discoverable | P105: A certification issued and published by somebody other than the provider. Canada runs the only public, tiered insurance API certification programme in the world (CSIO) and it was invisible to the score — its own table lists the country's largest P&C insurer as Not Yet Rated while smaller competitors hold higher tiers, which is exactly the published signal a rubric should read. THE CAUTION THIS CHECK CARRIES, learned from real estate: RESO certification is real, independently tested and industry-mandated, and it is worth 2.0 points of measured difference — because all three certified organizations return 401 on the very contract they are certified against. A certification claim is credited here only alongside `servers_resolvable`; a badge for a document the consumer cannot fetch is not conformance. | T105: always | U105: insurance,health,energy_utilities,telecommunications | V105: =$N105-ROW()/100000
A106: Regulatory Posture | B106: Regulatory Posture | C106: reg_camara_conformance | D106: CAMARA / network-API conformance | E106: 6 | F106: =IF(AND($U106<>"",REGIME="none"),"N/A",IF(AND($U106<>"",$U106<>"any",ISERROR(SEARCH(REGIME,$U106))),"N/A",IF(VLOOKUP($T106,GATES,2,FALSE)="Yes","Yes","N/A"))) | G106: No | I106: — | J106: =IFERROR(VLOOKUP($I106,PROV_CREDIT,2,FALSE),1) | K106: =IF($F106="N/A",0,$E106*IF(ISNUMBER($H106),MEDIAN(0,$H106,1),IF($G106="Yes",1,IF($G106="Partial",0.5,0)))*$J106) | L106: =IF($F106="N/A",0,$E106) | M106: =$L106-$K106 | N106: =IF($L106=0,0,ROUND($M106/SUMIF($B$2:$B$107,$B106,$L$2:$L$107)*100*IFERROR(VLOOKUP($B106,Scorecard!$A$6:$C$12,3,FALSE),0),2)) | O106: an x-camara-commonalities version, /camara/ paths, CIBA support, or TM Forum Open API conformance | P106: Conformance to the network-API standards the sector actually built: CAMARA commonalities, the canonical API definitions, CIBA (the backchannel authentication flow CAMARA specifies for network authorization, found in 3 of 19 standards repositories and absent from both specs of the one exposure platform with a callable endpoint), and TM Forum Open API conformance — held widely by carriers who publish no network API at all. | T106: always | U106: telecommunications | V106: =$N106-ROW()/100000
A107: Regulatory Posture | B107: Regulatory Posture | C107: reg_mandate_verified | D107: Mandate implemented, not merely claimed | E107: 8 | F107: =IF(AND($U107<>"",REGIME="none"),"N/A",IF(AND($U107<>"",$U107<>"any",ISERROR(SEARCH(REGIME,$U107))),"N/A",IF(VLOOKUP($T107,GATES,2,FALSE)="Yes","Yes","N/A"))) | G107: No | I107: — | J107: =IFERROR(VLOOKUP($I107,PROV_CREDIT,2,FALSE),1) | K107: =IF($F107="N/A",0,$E107*IF(ISNUMBER($H107),MEDIAN(0,$H107,1),IF($G107="Yes",1,IF($G107="Partial",0.5,0)))*$J107) | L107: =IF($F107="N/A",0,$E107) | M107: =$L107-$K107 | N107: =IF($L107=0,0,ROUND($M107/SUMIF($B$2:$B$107,$B107,$L$2:$L$107)*100*IFERROR(VLOOKUP($B107,Scorecard!$A$6:$C$12,3,FALSE),0),2)) | O107: the mandated surface is evidenced by a resolvable endpoint, register entry or conformant discovery document — not by a compliance page | P107: THE LARGEST UNMEASURED EFFECT IN THE CATALOG, and the reason it lands in 0.6 rather than waiting. Across 95 energy organizations scored on a deliberately ruthless mandate ladder, a VERIFIED mandate was worth about twelve points of composite — live-implemented 42.2 against not-applicable 36.6 — while a CLAIMED-but-unverifiable mandate scored 30.4, BELOW the 30.2 of organizations under no obligation at all. That second number is the finding. Self-declared compliance is not merely uninformative, it is NEGATIVE signal, and any assessment that reads compliance pages instead of calling endpoints will rank the field backwards at the top. Compare RESO in real estate at 2.0 points: same question, two sectors, a six-fold difference in effect, because one mandate came with a public register and conformant discovery endpoints and the other came with a badge. The failure mode is already live here: two Ontario utilities present as Green Button compliant and cannot be verified, one because its onboarding host returns HTTP 200 for every path including invented ones, being a single-page-app catch-all. Without a verification state that provider scores as compliant. | T107: always | U107: banking_open_finance,energy_utilities,health | V107: =$N107-ROW()/100000

Sheet Agent Readiness
A1: Agent Readiness
A2: Score (0–100) | C2: =IF(SUM($C$7:$C$20)=0,0,ROUND(SUM($J$7:$J$20)/SUM($C$7:$C$20)*100,1))
A3: Band | C3: =IF(AND(IF($C$2>=46,"Agent-Native",IF($C$2>=34,"Agent-Ready",IF($C$2>=6,"Agent-Aware","Human-Only")))="Agent-Native",OR($H11=0,$H12=0)),"Agent-Ready",IF($C$2>=46,"Agent-Native",IF($C$2>=34,"Agent-Ready",IF($C$2>=6,"Agent-Aware","Human-Only"))))
A4: How safely an autonomous AI agent — not just a human developer — can drive this API. Measures machine-readable contracts, agent-native access controls, and the operational signals (idempotency, stable errors, rate-limit state) an agent needs to act without a human papering over the gaps.
A5: Band gate: Agent-Native is withheld unless idempotency AND stable error semantics both score. Every dimension is always in the denominator — unlike the composite, a missing contract here is a real deficiency, not an N/A.
A6: Dimension | B6: ID | C6: Points | D6: Grades available | E6: Your grade | F6: Documented credit | G6: Authorship | H6: Credit | I6: Prov. credit | J6: Earned | K6: Gap | L6: What the scorer looks for | M6: Why it matters | N6: Owner | O6: Target | P6: Notes
A7: Machine-Readable Contract | B7: spec_presence | C7: 18 | D7: no, yes | E7: no | F7: 0 | G7: — | H7: =IF($E7="no",0,IF(OR($E7="yes",$E7="verified",$E7="conformant"),1,IF($E7="near-conformant",0.6,IF($E7="partial",0.5,IF($E7="documented",$F7,IF($E7="flavored",0.25,0)))))) | I7: =IFERROR(VLOOKUP($G7,PROV_CREDIT,2,FALSE),1) | J7: =$C7*$H7*$I7 | K7: =$C7-$J7 | L7: api_specs includes an OpenAPI document | M7: A public OpenAPI contract exists. Agents call APIs from contracts, not HTML docs — with no spec there is no programmatic surface to drive, which is why this is the single largest award.
A8: Agentic Access Contract | B8: agentic_access | C8: 10 | D8: no, yes | E8: no | F8: 0 | G8: first-party | H8: =IF($E8="no",0,IF(OR($E8="yes",$E8="verified",$E8="conformant"),1,IF($E8="near-conformant",0.6,IF($E8="partial",0.5,IF($E8="documented",$F8,IF($E8="flavored",0.25,0)))))) | I8: =IFERROR(VLOOKUP($G8,PROV_CREDIT,2,FALSE),1) | J8: =$C8*$H8*$I8 | K8: =$C8-$J8 | L8: agentic_access artifact present (x-agentic-access), graded by author | M8: The provider publishes an x-agentic-access contract classifying each operation by action-class, consequence, and human-in-the-loop escalation. The most explicit "this API was designed to be driven by an agent" signal in the catalog — when the provider publishes it. A derived classification keeps a floor: it is a real artifact an agent can fetch and act on, it is simply not evidence about the provider's design intent.
A9: MCP Server | B9: mcp_server | C9: 12 | D9: no, yes | E9: no | F9: 0 | G9: first-party | H9: =IF($E9="no",0,IF(OR($E9="yes",$E9="verified",$E9="conformant"),1,IF($E9="near-conformant",0.6,IF($E9="partial",0.5,IF($E9="documented",$F9,IF($E9="flavored",0.25,0)))))) | I9: =IFERROR(VLOOKUP($G9,PROV_CREDIT,2,FALSE),1) | J9: =$C9*$H9*$I9 | K9: =$C9-$J9 | L9: common[].type includes MCPServer, graded by whether the provider runs it | M9: A Model Context Protocol server makes the API directly callable by agents over a uniform tool surface — the most direct expression of agent-first design. PROVENANCE-GRADED IN 0.6. Across four national banking markets exactly one institution ran a genuinely hosted MCP; in UK insurance the data credited 14.3% of the cohort and the real number was zero. Catalog-wide, 1,882 of 3,046 MCP artifacts are derived candidates with no URL. Twelve points is the third-largest award in this model and it was being paid, more often than not, for a server nobody can connect to.
A10: Machine-Readable Auth | B10: auth_clarity | C10: 10 | D10: no, yes | E10: no | F10: 0 | G10: — | H10: =IF($E10="no",0,IF(OR($E10="yes",$E10="verified",$E10="conformant"),1,IF($E10="near-conformant",0.6,IF($E10="partial",0.5,IF($E10="documented",$F10,IF($E10="flavored",0.25,0)))))) | I10: =IFERROR(VLOOKUP($G10,PROV_CREDIT,2,FALSE),1) | J10: =$C10*$H10*$I10 | K10: =$C10-$J10 | L10: common[].type includes Authentication, OpenIDConnect, OAuthScopes, or API Keys | M10: The authentication model is documented in a form an agent can negotiate without reading prose — OIDC discovery, declared scopes, or OpenAPI security schemes.
A11: Idempotency | B11: idempotency | C11: 9 | D11: no, verified, documented | E11: no | F11: 0.5 | G11: — | H11: =IF($E11="no",0,IF(OR($E11="yes",$E11="verified",$E11="conformant"),1,IF($E11="near-conformant",0.6,IF($E11="partial",0.5,IF($E11="documented",$F11,IF($E11="flavored",0.25,0)))))) | I11: =IFERROR(VLOOKUP($G11,PROV_CREDIT,2,FALSE),1) | J11: =$C11*$H11*$I11 | K11: =$C11-$J11 | L11: OpenAPI mutating operations declare an Idempotency-Key header (verified), else common[].type matches /idempoten/i (documented) | M11: Mutating operations accept an idempotency key. Agents retry; without idempotency a retry double-charges a card, sends a message twice, or opens a duplicate ticket. Full credit requires the parameter to appear on POST / PATCH / PUT operations in the contract — the difference between a provider saying they support it and a contract an agent can act on.
A12: Stable Error Semantics | B12: error_semantics | C12: 8 | D12: no, verified, documented | E12: no | F12: 0.5 | G12: — | H12: =IF($E12="no",0,IF(OR($E12="yes",$E12="verified",$E12="conformant"),1,IF($E12="near-conformant",0.6,IF($E12="partial",0.5,IF($E12="documented",$F12,IF($E12="flavored",0.25,0)))))) | I12: =IFERROR(VLOOKUP($G12,PROV_CREDIT,2,FALSE),1) | J12: =$C12*$H12*$I12 | K12: =$C12-$J12 | L12: OpenAPI $refs a shared error schema across 4xx/5xx responses (verified), else common[].type includes ErrorCatalog / ErrorCodes / DeclineCodes | M12: Errors are a documented, stable envelope with stable codes. Agents branch on errors — free-text messages break that branching and send an agent into blind retries. Full credit requires a single error schema referenced across error responses: a typed envelope, not a catalogue of codes in a table.
A13: Request/Response Examples | B13: openapi_examples | C13: 7 | D13: no, verified, partial, documented | E13: no | F13: 0.25 | G13: — | H13: =IF($E13="no",0,IF(OR($E13="yes",$E13="verified",$E13="conformant"),1,IF($E13="near-conformant",0.6,IF($E13="partial",0.5,IF($E13="documented",$F13,IF($E13="flavored",0.25,0)))))) | I13: =IFERROR(VLOOKUP($G13,PROV_CREDIT,2,FALSE),1) | J13: =$C13*$H13*$I13 | K13: =$C13-$J13 | L13: share of operations carrying request/response examples; else an Examples / Code Samples link | M13: Meaningful examples are published. Examples are the cheapest way an agent learns a payload shape before it ever makes a call. Graded in 0.6 because as a bit it ran at roughly 0% across payments and healthcare and discriminated between nobody: full credit at 50%+ of operations carrying an example, half below that, a quarter for a documentation link alone.
A14: Rate-Limit Signaling | B14: rate_limit_signal | C14: 7 | D14: no, verified, documented | E14: no | F14: 0.5 | G14: — | H14: =IF($E14="no",0,IF(OR($E14="yes",$E14="verified",$E14="conformant"),1,IF($E14="near-conformant",0.6,IF($E14="partial",0.5,IF($E14="documented",$F14,IF($E14="flavored",0.25,0)))))) | I14: =IFERROR(VLOOKUP($G14,PROV_CREDIT,2,FALSE),1) | J14: =$C14*$H14*$I14 | K14: =$C14-$J14 | L14: OpenAPI responses document X-RateLimit-* / RateLimit headers (verified), else a rate_limits artifact or RateLimits link (documented) | M14: Rate-limit behaviour is documented as machine-readable data. An agent needs to know when to back off; "you will get a 429 eventually" is not something it can plan against. Full credit requires the API to surface live rate-limit state in RESPONSE HEADERS, which is what an agent reads mid-run — documented limits tell it the ceiling, headers tell it where it is.
A15: Typed Event Surface | B15: event_surface_described | C15: 6 | D15: no, yes | E15: no | F15: 0 | G15: first-party | H15: =IF($E15="no",0,IF(OR($E15="yes",$E15="verified",$E15="conformant"),1,IF($E15="near-conformant",0.6,IF($E15="partial",0.5,IF($E15="documented",$F15,IF($E15="flavored",0.25,0)))))) | I15: =IFERROR(VLOOKUP($G15,PROV_CREDIT,2,FALSE),1) | J15: =$C15*$H15*$I15 | K15: =$C15-$J15 | L15: AsyncAPI document, OR webhooks/callbacks objects in the as-published OpenAPI, OR common[].type includes Webhooks | M15: Event and webhook surfaces are described by a contract, so an agent that must react to state changes has a typed surface rather than example payloads. RENAMED AND WIDENED IN 0.9 — it was `asyncapi_events` and read only the asyncapi/ directory, which named the artifact rather than the capability and scored a provider false for describing their events the other legal way. A webhook can be described in OpenAPI: 3.1 added a top-level `webhooks` object and `callbacks` predates it. In this catalog 125 providers do exactly that — 87 via `webhooks` across 2,218 events, 39 via `callbacks` — against ZERO who publish AsyncAPI. Both count, equally: the dimension asks whether an agent can read the event surface, not which specification the provider chose to write it in.
A16: Agent Skills | B16: agent_skills | C16: 5 | D16: no, yes | E16: no | F16: 0 | G16: first-party | H16: =IF($E16="no",0,IF(OR($E16="yes",$E16="verified",$E16="conformant"),1,IF($E16="near-conformant",0.6,IF($E16="partial",0.5,IF($E16="documented",$F16,IF($E16="flavored",0.25,0)))))) | I16: =IFERROR(VLOOKUP($G16,PROV_CREDIT,2,FALSE),1) | J16: =$C16*$H16*$I16 | K16: =$C16-$J16 | L16: skills artifact present, graded by who authored it | M16: Packaged operating instructions an agent should follow when using the API, rather than leaving usage to be inferred from the spec. PROVENANCE-GRADED IN 0.6: 2,018 of 2,274 skill sets in the catalog are API-Evangelist-generated. In UK insurance all 27 were; across all of telecom, provider-published agent skills exist at exactly three companies.
A17: Well-Known Catalog | B17: well_known_catalog | C17: 4 | D17: no, yes | E17: no | F17: 0 | G17: — | H17: =IF($E17="no",0,IF(OR($E17="yes",$E17="verified",$E17="conformant"),1,IF($E17="near-conformant",0.6,IF($E17="partial",0.5,IF($E17="documented",$F17,IF($E17="flavored",0.25,0)))))) | I17: =IFERROR(VLOOKUP($G17,PROV_CREDIT,2,FALSE),1) | J17: =$C17*$H17*$I17 | K17: =$C17-$J17 | L17: common[].type includes WellKnown, APICatalog, or api-catalog | M17: A /.well-known/api-catalog (RFC 9727) linkset — the canonical machine entrypoint an agent hits first to discover the provider's APIs and MCP endpoints.
A18: Consent & Bot Identity | B18: consent_identity | C18: 3 | D18: no, yes | E18: no | F18: 0 | G18: — | H18: =IF($E18="no",0,IF(OR($E18="yes",$E18="verified",$E18="conformant"),1,IF($E18="near-conformant",0.6,IF($E18="partial",0.5,IF($E18="documented",$F18,IF($E18="flavored",0.25,0)))))) | I18: =IFERROR(VLOOKUP($G18,PROV_CREDIT,2,FALSE),1) | J18: =$C18*$H18*$I18 | K18: =$C18-$J18 | L18: common[].type includes AIPREF, ContentSignal, WebBotAuth, HTTPMessageSignatures, or SecurityTxt | M18: Forward-looking signals for machine-readable AI usage preferences (AIPREF, Content-Signals) and cryptographically identified agent traffic (Web Bot Auth / RFC 9421). Rare today; rewards the providers defining the frontier.
... A20: Dry-Run / Simulate Mode | B20: dry_run_mode | C20: 4 | D20: no, yes | E20: no | F20: 0 | G20: — | H20: =IF($E20="no",0,IF(OR($E20="yes",$E20="verified",$E20="conformant"),1,IF($E20="near-conformant",0.6,IF($E20="partial",0.5,IF($E20="documented",$F20,IF($E20="flavored",0.25,0)))))) | I20: =IFERROR(VLOOKUP($G20,PROV_CREDIT,2,FALSE),1) | J20: =$C20*$H20*$I20 | K20: =$C20-$J20 | L20: OpenAPI: destructive operations expose a dry_run / simulate / preview / validate_only parameter | M20: A destructive operation can be planned before it is committed. This is the safest agent-native affordance in existence and the rarest: it lets an agent show a human what it is about to do, or check its own work, without doing it. Every other safety rail in this model limits the damage of an action that has already happened; this one is the only dimension that prevents it.
A21: TOTAL | C21: =SUM($C$7:$C$20) | J21: =ROUND(SUM($J$7:$J$20),1) | K21: =ROUND(SUM($K$7:$K$20),1)

Sheet Priorities
A1: Do these next
A2: Ranked by how much composite score each unfinished check is worth to YOU right now — its points, divided by the denominator of its facet, times that facet's weight. Recalculates as you tick things off on the Checklist. Small facets move fast: a 6-point governance check can outrank a 20-point contract check.
A3: # | B3: Check | C3: Facet | D3: Worth on your score | E3: Points | F3: Artifact | G3: What the scorer looks for | H3: Owner | I3: Target | J3: _key
A4: 1 | B4: =IF($D4<=0,"",INDEX(Checklist!$D$2:$D$107,MATCH($J4,Checklist!$V$2:$V$107,0))) | C4: =IF($D4<=0,"",INDEX(Checklist!$B$2:$B$107,MATCH($J4,Checklist!$V$2:$V$107,0))) | D4: =ROUND(MAX(0,INDEX(Checklist!$N$2:$N$107,MATCH($J4,Checklist!$V$2:$V$107,0))),2) | E4: =IF($D4<=0,"",INDEX(Checklist!$E$2:$E$107,MATCH($J4,Checklist!$V$2:$V$107,0))) | F4: =IF($D4<=0,"",INDEX(Checklist!$A$2:$A$107,MATCH($J4,Checklist!$V$2:$V$107,0))) | G4: =IF($D4<=0,"",INDEX(Checklist!$O$2:$O$107,MATCH($J4,Checklist!$V$2:$V$107,0))) | J4: =LARGE(Checklist!$V$2:$V$107,1)
A5: 2 | B5: =IF($D5<=0,"",INDEX(Checklist!$D$2:$D$107,MATCH($J5,Checklist!$V$2:$V$107,0))) | C5: =IF($D5<=0,"",INDEX(Checklist!$B$2:$B$107,MATCH($J5,Checklist!$V$2:$V$107,0))) | D5: =ROUND(MAX(0,INDEX(Checklist!$N$2:$N$107,MATCH($J5,Checklist!$V$2:$V$107,0))),2) | E5: =IF($D5<=0,"",INDEX(Checklist!$E$2:$E$107,MATCH($J5,Checklist!$V$2:$V$107,0))) | F5: =IF($D5<=0,"",INDEX(Checklist!$A$2:$A$107,MATCH($J5,Checklist!$V$2:$V$107,0))) | G5: =IF($D5<=0,"",INDEX(Checklist!$O$2:$O$107,MATCH($J5,Checklist!$V$2:$V$107,0))) | J5: =LARGE(Checklist!$V$2:$V$107,2)
A6: 3 | B6: =IF($D6<=0,"",INDEX(Checklist!$D$2:$D$107,MATCH($J6,Checklist!$V$2:$V$107,0))) | C6: =IF($D6<=0,"",INDEX(Checklist!$B$2:$B$107,MATCH($J6,Checklist!$V$2:$V$107,0))) | D6: =ROUND(MAX(0,INDEX(Checklist!$N$2:$N$107,MATCH($J6,Checklist!$V$2:$V$107,0))),2) | E6: =IF($D6<=0,"",INDEX(Checklist!$E$2:$E$107,MATCH($J6,Checklist!$V$2:$V$107,0))) | F6: =IF($D6<=0,"",INDEX(Checklist!$A$2:$A$107,MATCH($J6,Checklist!$V$2:$V$107,0))) | G6: =IF($D6<=0,"",INDEX(Checklist!$O$2:$O$107,MATCH($J6,Checklist!$V$2:$V$107,0))) | J6: =LARGE(Checklist!$V$2:$V$107,3)
A7: 4 | B7: =IF($D7<=0,"",INDEX(Checklist!$D$2:$D$107,MATCH($J7,Checklist!$V$2:$V$107,0))) | C7: =IF($D7<=0,"",INDEX(Checklist!$B$2:$B$107,MATCH($J7,Checklist!$V$2:$V$107,0))) | D7: =ROUND(MAX(0,INDEX(Checklist!$N$2:$N$107,MATCH($J7,Checklist!$V$2:$V$107,0))),2) | E7: =IF($D7<=0,"",INDEX(Checklist!$E$2:$E$107,MATCH($J7,Checklist!$V$2:$V$107,0))) | F7: =IF($D7<=0,"",INDEX(Checklist!$A$2:$A$107,MATCH($J7,Checklist!$V$2:$V$107,0))) | G7: =IF($D7<=0,"",INDEX(Checklist!$O$2:$O$107,MATCH($J7,Checklist!$V$2:$V$107,0))) | J7: =LARGE(Checklist!$V$2:$V$107,4)
A8: 5 | B8: =IF($D8<=0,"",INDEX(Checklist!$D$2:$D$107,MATCH($J8,Checklist!$V$2:$V$107,0))) | C8: =IF($D8<=0,"",INDEX(Checklist!$B$2:$B$107,MATCH($J8,Checklist!$V$2:$V$107,0))) | D8: =ROUND(MAX(0,INDEX(Checklist!$N$2:$N$107,MATCH($J8,Checklist!$V$2:$V$107,0))),2) | E8: =IF($D8<=0,"",INDEX(Checklist!$E$2:$E$107,MATCH($J8,Checklist!$V$2:$V$107,0))) | F8: =IF($D8<=0,"",INDEX(Checklist!$A$2:$A$107,MATCH($J8,Checklist!$V$2:$V$107,0))) | G8: =IF($D8<=0,"",INDEX(Checklist!$O$2:$O$107,MATCH($J8,Checklist!$V$2:$V$107,0))) | J8: =LARGE(Checklist!$V$2:$V$107,5)
A9: 6 | B9: =IF($D9<=0,"",INDEX(Checklist!$D$2:$D$107,MATCH($J9,Checklist!$V$2:$V$107,0))) | C9: =IF($D9<=0,"",INDEX(Checklist!$B$2:$B$107,MATCH($J9,Checklist!$V$2:$V$107,0))) | D9: =ROUND(MAX(0,INDEX(Checklist!$N$2:$N$107,MATCH($J9,Checklist!$V$2:$V$107,0))),2) | E9: =IF($D9<=0,"",INDEX(Checklist!$E$2:$E$107,MATCH($J9,Checklist!$V$2:$V$107,0))) | F9: =IF($D9<=0,"",INDEX(Checklist!$A$2:$A$107,MATCH($J9,Checklist!$V$2:$V$107,0))) | G9: =IF($D9<=0,"",INDEX(Checklist!$O$2:$O$107,MATCH($J9,Checklist!$V$2:$V$107,0))) | J9: =LARGE(Checklist!$V$2:$V$107,6)
A10: 7 | B10: =IF($D10<=0,"",INDEX(Checklist!$D$2:$D$107,MATCH($J10,Checklist!$V$2:$V$107,0))) | C10: =IF($D10<=0,"",INDEX(Checklist!$B$2:$B$107,MATCH($J10,Checklist!$V$2:$V$107,0))) | D10: =ROUND(MAX(0,INDEX(Checklist!$N$2:$N$107,MATCH($J10,Checklist!$V$2:$V$107,0))),2) | E10: =IF($D10<=0,"",INDEX(Checklist!$E$2:$E$107,MATCH($J10,Checklist!$V$2:$V$107,0))) | F10: =IF($D10<=0,"",INDEX(Checklist!$A$2:$A$107,MATCH($J10,Checklist!$V$2:$V$107,0))) | G10: =IF($D10<=0,"",INDEX(Checklist!$O$2:$O$107,MATCH($J10,Checklist!$V$2:$V$107,0))) | J10: =LARGE(Checklist!$V$2:$V$107,7)
A11: 8 | B11: =IF($D11<=0,"",INDEX(Checklist!$D$2:$D$107,MATCH($J11,Checklist!$V$2:$V$107,0))) | C11: =IF($D11<=0,"",INDEX(Checklist!$B$2:$B$107,MATCH($J11,Checklist!$V$2:$V$107,0))) | D11: =ROUND(MAX(0,INDEX(Checklist!$N$2:$N$107,MATCH($J11,Checklist!$V$2:$V$107,0))),2) | E11: =IF($D11<=0,"",INDEX(Checklist!$E$2:$E$107,MATCH($J11,Checklist!$V$2:$V$107,0))) | F11: =IF($D11<=0,"",INDEX(Checklist!$A$2:$A$107,MATCH($J11,Checklist!$V$2:$V$107,0))) | G11: =IF($D11<=0,"",INDEX(Checklist!$O$2:$O$107,MATCH($J11,Checklist!$V$2:$V$107,0))) | J11: =LARGE(Checklist!$V$2:$V$107,8)
A12: 9 | B12: =IF($D12<=0,"",INDEX(Checklist!$D$2:$D$107,MATCH($J12,Checklist!$V$2:$V$107,0))) | C12: =IF($D12<=0,"",INDEX(Checklist!$B$2:$B$107,MATCH($J12,Checklist!$V$2:$V$107,0))) | D12: =ROUND(MAX(0,INDEX(Checklist!$N$2:$N$107,MATCH($J12,Checklist!$V$2:$V$107,0))),2) | E12: =IF($D12<=0,"",INDEX(Checklist!$E$2:$E$107,MATCH($J12,Checklist!$V$2:$V$107,0))) | F12: =IF($D12<=0,"",INDEX(Checklist!$A$2:$A$107,MATCH($J12,Checklist!$V$2:$V$107,0))) | G12: =IF($D12<=0,"",INDEX(Checklist!$O$2:$O$107,MATCH($J12,Checklist!$V$2:$V$107,0))) | J12: =LARGE(Checklist!$V$2:$V$107,9)
A13: 10 | B13: =IF($D13<=0,"",INDEX(Checklist!$D$2:$D$107,MATCH($J13,Checklist!$V$2:$V$107,0))) | C13: =IF($D13<=0,"",INDEX(Checklist!$B$2:$B$107,MATCH($J13,Checklist!$V$2:$V$107,0))) | D13: =ROUND(MAX(0,INDEX(Checklist!$N$2:$N$107,MATCH($J13,Checklist!$V$2:$V$107,0))),2) | E13: =IF($D13<=0,"",INDEX(Checklist!$E$2:$E$107,MATCH($J13,Checklist!$V$2:$V$107,0))) | F13: =IF($D13<=0,"",INDEX(Checklist!$A$2:$A$107,MATCH($J13,Checklist!$V$2:$V$107,0))) | G13: =IF($D13<=0,"",INDEX(Checklist!$O$2:$O$107,MATCH($J13,Checklist!$V$2:$V$107,0))) | J13: =LARGE(Checklist!$V$2:$V$107,10)
A14: 11 | B14: =IF($D14<=0,"",INDEX(Checklist!$D$2:$D$107,MATCH($J14,Checklist!$V$2:$V$107,0))) | C14: =IF($D14<=0,"",INDEX(Checklist!$B$2:$B$107,MATCH($J14,Checklist!$V$2:$V$107,0))) | D14: =ROUND(MAX(0,INDEX(Checklist!$N$2:$N$107,MATCH($J14,Checklist!$V$2:$V$107,0))),2) | E14: =IF($D14<=0,"",INDEX(Checklist!$E$2:$E$107,MATCH($J14,Checklist!$V$2:$V$107,0))) | F14: =IF($D14<=0,"",INDEX(Checklist!$A$2:$A$107,MATCH($J14,Checklist!$V$2:$V$107,0))) | G14: =IF($D14<=0,"",INDEX(Checklist!$O$2:$O$107,MATCH($J14,Checklist!$V$2:$V$107,0))) | J14: =LARGE(Checklist!$V$2:$V$107,11)
A15: 12 | B15: =IF($D15<=0,"",INDEX(Checklist!$D$2:$D$107,MATCH($J15,Checklist!$V$2:$V$107,0))) | C15: =IF($D15<=0,"",INDEX(Checklist!$B$2:$B$107,MATCH($J15,Checklist!$V$2:$V$107,0))) | D15: =ROUND(MAX(0,INDEX(Checklist!$N$2:$N$107,MATCH($J15,Checklist!$V$2:$V$107,0))),2) | E15: =IF($D15<=0,"",INDEX(Checklist!$E$2:$E$107,MATCH($J15,Checklist!$V$2:$V$107,0))) | F15: =IF($D15<=0,"",INDEX(Checklist!$A$2:$A$107,MATCH($J15,Checklist!$V$2:$V$107,0))) | G15: =IF($D15<=0,"",INDEX(Checklist!$O$2:$O$107,MATCH($J15,Checklist!$V$2:$V$107,0))) | J15: =LARGE(Checklist!$V$2:$V$107,12)
A16: 13 | B16: =IF($D16<=0,"",INDEX(Checklist!$D$2:$D$107,MATCH($J16,Checklist!$V$2:$V$107,0))) | C16: =IF($D16<=0,"",INDEX(Checklist!$B$2:$B$107,MATCH($J16,Checklist!$V$2:$V$107,0))) | D16: =ROUND(MAX(0,INDEX(Checklist!$N$2:$N$107,MATCH($J16,Checklist!$V$2:$V$107,0))),2) | E16: =IF($D16<=0,"",INDEX(Checklist!$E$2:$E$107,MATCH($J16,Checklist!$V$2:$V$107,0))) | F16: =IF($D16<=0,"",INDEX(Checklist!$A$2:$A$107,MATCH($J16,Checklist!$V$2:$V$107,0))) | G16: =IF($D16<=0,"",INDEX(Checklist!$O$2:$O$107,MATCH($J16,Checklist!$V$2:$V$107,0))) | J16: =LARGE(Checklist!$V$2:$V$107,13)
A17: 14 | B17: =IF($D17<=0,"",INDEX(Checklist!$D$2:$D$107,MATCH($J17,Checklist!$V$2:$V$107,0))) | C17: =IF($D17<=0,"",INDEX(Checklist!$B$2:$B$107,MATCH($J17,Checklist!$V$2:$V$107,0))) | D17: =ROUND(MAX(0,INDEX(Checklist!$N$2:$N$107,MATCH($J17,Checklist!$V$2:$V$107,0))),2) | E17: =IF($D17<=0,"",INDEX(Checklist!$E$2:$E$107,MATCH($J17,Checklist!$V$2:$V$107,0))) | F17: =IF($D17<=0,"",INDEX(Checklist!$A$2:$A$107,MATCH($J17,Checklist!$V$2:$V$107,0))) | G17: =IF($D17<=0,"",INDEX(Checklist!$O$2:$O$107,MATCH($J17,Checklist!$V$2:$V$107,0))) | J17: =LARGE(Checklist!$V$2:$V$107,14)
A18: 15 | B18: =IF($D18<=0,"",INDEX(Checklist!$D$2:$D$107,MATCH($J18,Checklist!$V$2:$V$107,0))) | C18: =IF($D18<=0,"",INDEX(Checklist!$B$2:$B$107,MATCH($J18,Checklist!$V$2:$V$107,0))) | D18: =ROUND(MAX(0,INDEX(Checklist!$N$2:$N$107,MATCH($J18,Checklist!$V$2:$V$107,0))),2) | E18: =IF($D18<=0,"",INDEX(Checklist!$E$2:$E$107,MATCH($J18,Checklist!$V$2:$V$107,0))) | F18: =IF($D18<=0,"",INDEX(Checklist!$A$2:$A$107,MATCH($J18,Checklist!$V$2:$V$107,0))) | G18: =IF($D18<=0,"",INDEX(Checklist!$O$2:$O$107,MATCH($J18,Checklist!$V$2:$V$107,0))) | J18: =LARGE(Checklist!$V$2:$V$107,15)
A19: 16 | B19: =IF($D19<=0,"",INDEX(Checklist!$D$2:$D$107,MATCH($J19,Checklist!$V$2:$V$107,0))) | C19: =IF($D19<=0,"",INDEX(Checklist!$B$2:$B$107,MATCH($J19,Checklist!$V$2:$V$107,0))) | D19: =ROUND(MAX(0,INDEX(Checklist!$N$2:$N$107,MATCH($J19,Checklist!$V$2:$V$107,0))),2) | E19: =IF($D19<=0,"",INDEX(Checklist!$E$2:$E$107,MATCH($J19,Checklist!$V$2:$V$107,0))) | F19: =IF($D19<=0,"",INDEX(Checklist!$A$2:$A$107,MATCH($J19,Checklist!$V$2:$V$107,0))) | G19: =IF($D19<=0,"",INDEX(Checklist!$O$2:$O$107,MATCH($J19,Checklist!$V$2:$V$107,0))) | J19: =LARGE(Checklist!$V$2:$V$107,16)
A20: 17 | B20: =IF($D20<=0,"",INDEX(Checklist!$D$2:$D$107,MATCH($J20,Checklist!$V$2:$V$107,0))) | C20: =IF($D20<=0,"",INDEX(Checklist!$B$2:$B$107,MATCH($J20,Checklist!$V$2:$V$107,0))) | D20: =ROUND(MAX(0,INDEX(Checklist!$N$2:$N$107,MATCH($J20,Checklist!$V$2:$V$107,0))),2) | E20: =IF($D20<=0,"",INDEX(Checklist!$E$2:$E$107,MATCH($J20,Checklist!$V$2:$V$107,0))) | F20: =IF($D20<=0,"",INDEX(Checklist!$A$2:$A$107,MATCH($J20,Checklist!$V$2:$V$107,0))) | G20: =IF($D20<=0,"",INDEX(Checklist!$O$2:$O$107,MATCH($J20,Checklist!$V$2:$V$107,0))) | J20: =LARGE(Checklist!$V$2:$V$107,17)
A21: 18 | B21: =IF($D21<=0,"",INDEX(Checklist!$D$2:$D$107,MATCH($J21,Checklist!$V$2:$V$107,0))) | C21: =IF($D21<=0,"",INDEX(Checklist!$B$2:$B$107,MATCH($J21,Checklist!$V$2:$V$107,0))) | D21: =ROUND(MAX(0,INDEX(Checklist!$N$2:$N$107,MATCH($J21,Checklist!$V$2:$V$107,0))),2) | E21: =IF($D21<=0,"",INDEX(Checklist!$E$2:$E$107,MATCH($J21,Checklist!$V$2:$V$107,0))) | F21: =IF($D21<=0,"",INDEX(Checklist!$A$2:$A$107,MATCH($J21,Checklist!$V$2:$V$107,0))) | G21: =IF($D21<=0,"",INDEX(Checklist!$O$2:$O$107,MATCH($J21,Checklist!$V$2:$V$107,0))) | J21: =LARGE(Checklist!$V$2:$V$107,18)
A22: 19 | B22: =IF($D22<=0,"",INDEX(Checklist!$D$2:$D$107,MATCH($J22,Checklist!$V$2:$V$107,0))) | C22: =IF($D22<=0,"",INDEX(Checklist!$B$2:$B$107,MATCH($J22,Checklist!$V$2:$V$107,0))) | D22: =ROUND(MAX(0,INDEX(Checklist!$N$2:$N$107,MATCH($J22,Checklist!$V$2:$V$107,0))),2) | E22: =IF($D22<=0,"",INDEX(Checklist!$E$2:$E$107,MATCH($J22,Checklist!$V$2:$V$107,0))) | F22: =IF($D22<=0,"",INDEX(Checklist!$A$2:$A$107,MATCH($J22,Checklist!$V$2:$V$107,0))) | G22: =IF($D22<=0,"",INDEX(Checklist!$O$2:$O$107,MATCH($J22,Checklist!$V$2:$V$107,0))) | J22: =LARGE(Checklist!$V$2:$V$107,19)
A23: 20 | B23: =IF($D23<=0,"",INDEX(Checklist!$D$2:$D$107,MATCH($J23,Checklist!$V$2:$V$107,0))) | C23: =IF($D23<=0,"",INDEX(Checklist!$B$2:$B$107,MATCH($J23,Checklist!$V$2:$V$107,0))) | D23: =ROUND(MAX(0,INDEX(Checklist!$N$2:$N$107,MATCH($J23,Checklist!$V$2:$V$107,0))),2) | E23: =IF($D23<=0,"",INDEX(Checklist!$E$2:$E$107,MATCH($J23,Checklist!$V$2:$V$107,0))) | F23: =IF($D23<=0,"",INDEX(Checklist!$A$2:$A$107,MATCH($J23,Checklist!$V$2:$V$107,0))) | G23: =IF($D23<=0,"",INDEX(Checklist!$O$2:$O$107,MATCH($J23,Checklist!$V$2:$V$107,0))) | J23: =LARGE(Checklist!$V$2:$V$107,20)
A24: 21 | B24: =IF($D24<=0,"",INDEX(Checklist!$D$2:$D$107,MATCH($J24,Checklist!$V$2:$V$107,0))) | C24: =IF($D24<=0,"",INDEX(Checklist!$B$2:$B$107,MATCH($J24,Checklist!$V$2:$V$107,0))) | D24: =ROUND(MAX(0,INDEX(Checklist!$N$2:$N$107,MATCH($J24,Checklist!$V$2:$V$107,0))),2) | E24: =IF($D24<=0,"",INDEX(Checklist!$E$2:$E$107,MATCH($J24,Checklist!$V$2:$V$107,0))) | F24: =IF($D24<=0,"",INDEX(Checklist!$A$2:$A$107,MATCH($J24,Checklist!$V$2:$V$107,0))) | G24: =IF($D24<=0,"",INDEX(Checklist!$O$2:$O$107,MATCH($J24,Checklist!$V$2:$V$107,0))) | J24: =LARGE(Checklist!$V$2:$V$107,21)
A25: 22 | B25: =IF($D25<=0,"",INDEX(Checklist!$D$2:$D$107,MATCH($J25,Checklist!$V$2:$V$107,0))) | C25: =IF($D25<=0,"",INDEX(Checklist!$B$2:$B$107,MATCH($J25,Checklist!$V$2:$V$107,0))) | D25: =ROUND(MAX(0,INDEX(Checklist!$N$2:$N$107,MATCH($J25,Checklist!$V$2:$V$107,0))),2) | E25: =IF($D25<=0,"",INDEX(Checklist!$E$2:$E$107,MATCH($J25,Checklist!$V$2:$V$107,0))) | F25: =IF($D25<=0,"",INDEX(Checklist!$A$2:$A$107,MATCH($J25,Checklist!$V$2:$V$107,0))) | G25: =IF($D25<=0,"",INDEX(Checklist!$O$2:$O$107,MATCH($J25,Checklist!$V$2:$V$107,0))) | J25: =LARGE(Checklist!$V$2:$V$107,22)
A26: 23 | B26: =IF($D26<=0,"",INDEX(Checklist!$D$2:$D$107,MATCH($J26,Checklist!$V$2:$V$107,0))) | C26: =IF($D26<=0,"",INDEX(Checklist!$B$2:$B$107,MATCH($J26,Checklist!$V$2:$V$107,0))) | D26: =ROUND(MAX(0,INDEX(Checklist!$N$2:$N$107,MATCH($J26,Checklist!$V$2:$V$107,0))),2) | E26: =IF($D26<=0,"",INDEX(Checklist!$E$2:$E$107,MATCH($J26,Checklist!$V$2:$V$107,0))) | F26: =IF($D26<=0,"",INDEX(Checklist!$A$2:$A$107,MATCH($J26,Checklist!$V$2:$V$107,0))) | G26: =IF($D26<=0,"",INDEX(Checklist!$O$2:$O$107,MATCH($J26,Checklist!$V$2:$V$107,0))) | J26: =LARGE(Checklist!$V$2:$V$107,23)
